Workbook

Sheet Data Input
A1: MARLINE DATA INPUT — Single Source of Truth for All Portfolio Data
A2: COLOR LEGEND: | C2: Blue = Manual Input | E2: Red = YCharts Add-In (auto) | G2: Orange = DWA Import (paste) | I2: Light Blue = Market Data (auto) | K2: Black = Computed Formula
A4: PORTFOLIO ASSUMPTIONS
A5: Risk-Free Rate | B5: =IFERROR(ycps("^TNX","price")/100,0.045) -> 0.045 | C5: Auto from YCharts 10Y Treasury yield or manual override
A6: Benchmark Return | B6: =IFERROR(ycps("SPY","one_year_return"),0.1) -> 0.1 | C6: Auto from YCharts SPY 1Y return or manual
A7: Benchmark Vol | B7: =IFERROR(ycps("SPY","one_year_volatility"),0.16) -> 0.16 | C7: Auto from YCharts SPY 1Y volatility or manual
A8: Portfolio Value | B8: 100000 | C8: Total AUM — update monthly
A9: Rebalance Band (±%) | B9: 0.05 | C9: Drift threshold to trigger rebalance
A10: Max Single Asset | B10: 0.3 | C10: Position concentration limit
A11: Min Single Asset | B11: 0.02 | C11: Minimum meaningful position
A12: Max Equity | B12: 0.7 | C12: Total equity allocation cap
A13: Min Fixed Income | B13: 0.1 | C13: Minimum bond allocation floor
A14: Max Alternatives | B14: 0.25 | C14: Alternatives + MF + hedge cap
A17: LIVE MARKET DATA — YCharts Auto-Refresh
A18: S&P 500 Price | B18: =IFERROR(ycps("SPY","price"),"") | C18: SPY last price
A19: S&P 500 1Y Return | B19: =IFERROR(ycps("SPY","one_year_return"),"") | C19: Benchmark trailing 1Y
A20: Nasdaq 100 1Y Return | B20: =IFERROR(ycps("QQQ","one_year_return"),"") | C20: Growth benchmark
A21: VIX Level | B21: =IFERROR(ycps("^VIX","price"),18) -> 18 | C21: CBOE Volatility Index — feeds Buffered ETF regime
A22: 10-Year Treasury Yield | B22: =IFERROR(ycps("^TNX","price")/100,0.045) -> 0.045 | C22: Risk-free rate proxy
A23: 2-Year Treasury Yield | B23: =IFERROR(ycps("^IRX","price")/100,0.04) -> 0.04 | C23: Short-term rate
A24: Yield Curve Spread | B24: =B22-B23 -> 0.005 | C24: 10Y minus 2Y — inversion = recession risk
A25: US Dollar Index | B25: =IFERROR(ycps("UUP","price"),"") | C25: Dollar strength
A26: Gold Price | B26: =IFERROR(ycps("GLD","price"),"") | C26: Safe haven gauge
A27: High Yield Spread | B27: =IFERROR(ycps("HYG","dividend_yield")-ycps("AGG","dividend_yield"),"") | C27: Credit stress indicator
A28: Market Breadth (SPY RSI) | B28: =IFERROR(50+ycps("SPY","one_month_return")*300,50) -> 50 | C28: Breadth proxy 0-100
A29: Put/Call Ratio Proxy | B29: =IFERROR(100-B28,50) -> 50 | C29: Sentiment (inverse of breadth)
A32: FSM THRESHOLDS
A33: Fully Invested ≥ | B33: 0.7
A34: Caution ≥ | B34: 0.5
A35: Defensive ≥ | B35: 0.3
A36: Risk Off < | B36: 0.3
A38: CASH TRIGGER THRESHOLDS
A39: MMPR50 Trigger < | B39: 0.4
A40: MMPR70 Trigger < | B40: 0.25
A41: PR4050 Trigger < | B41: 45
A42: PR4080 Trigger < | B42: 40
A44: COMPOSITE SIGNAL WEIGHTS
A45: Trend Weight | B45: 0.3
A46: Technical Weight | B46: 0.25
A47: Fundamental Weight | B47: 0.25
...

Sheet Asset Analysis
A1: SECURITY ANALYSIS — Blue cells are inputs. All other cells are formulas.
A3: Ticker | B3: Class | C3: Type | D3: Ann Return | E3: Volatility | F3: Sharpe | G3: Sortino | H3: Beta | I3: Max DD | J3: 1M Mom | K3: 3M Mom | L3: 6M Mom | M3: 12M Mom | N3: DWA Score | O3: DWA Signal | P3: RS Rank | Q3: Target Wt | R3: Current Wt | S3: Drift | T3: Action
A4: ='Data Input'!A56 -> SPY | B4: ='Data Input'!B56 -> US Eq | C4: ='Data Input'!C56 -> ETF | D4: =IFERROR('Data Input'!E56,0) | E4: =IFERROR('Data Input'!H56,0) | F4: =IFERROR('Data Input'!V56,0) | G4: =IFERROR('Data Input'!W56,0) | H4: =IFERROR('Data Input'!J56,0) | I4: =IFERROR('Data Input'!I56,0) | J4: =IFERROR('Data Input'!M56,0) | K4: =IFERROR('Data Input'!N56,0) | L4: =IFERROR('Data Input'!O56,0) | M4: =IFERROR('Data Input'!P56,0) | N4: =IFERROR(IF('Data Input'!Q56<>"",'Data Input'!Q56,MIN(100,MAX(0,ROUND(50+(J4*0.4+K4*0.3+L4*0.2+M4*0.1)*200,0)))),0) -> 0 | O4: =IF('Data Input'!S56<>"",'Data Input'!S56,IF(N4>=70,"BUY",IF(N4>=50,"HOLD","SELL"))) -> SELL | P4: =RANK(N4,N$4:N$27,0) -> 1 | Q4: ='Data Input'!AD56 -> 0.08 | R4: ='Data Input'!AE56 -> 0.09 | S4: =R4-Q4 -> 0.01 | T4: =IF(ABS(S4)>'Data Input'!$B$9,"REBALANCE",IF(AND(O4="BUY",S4<0),"ADD",IF(AND(O4="SELL",S4>0),"TRIM","HOLD"))) -> TRIM
A5: ='Data Input'!A57 -> QQQ | B5: ='Data Input'!B57 -> US Eq | C5: ='Data Input'!C57 -> ETF | D5: =IFERROR('Data Input'!E57,0) | E5: =IFERROR('Data Input'!H57,0) | F5: =IFERROR('Data Input'!V57,0) | G5: =IFERROR('Data Input'!W57,0) | H5: =IFERROR('Data Input'!J57,0) | I5: =IFERROR('Data Input'!I57,0) | J5: =IFERROR('Data Input'!M57,0) | K5: =IFERROR('Data Input'!N57,0) | L5: =IFERROR('Data Input'!O57,0) | M5: =IFERROR('Data Input'!P57,0) | N5: =IFERROR(IF('Data Input'!Q57<>"",'Data Input'!Q57,MIN(100,MAX(0,ROUND(50+(J5*0.4+K5*0.3+L5*0.2+M5*0.1)*200,0)))),0) -> 0 | O5: =IF('Data Input'!S57<>"",'Data Input'!S57,IF(N5>=70,"BUY",IF(N5>=50,"HOLD","SELL"))) -> SELL | P5: =RANK(N5,N$4:N$27,0) -> 1 | Q5: ='Data Input'!AD57 -> 0.07 | R5: ='Data Input'!AE57 -> 0.065 | S5: =R5-Q5 -> -0.005 | T5: =IF(ABS(S5)>'Data Input'!$B$9,"REBALANCE",IF(AND(O5="BUY",S5<0),"ADD",IF(AND(O5="SELL",S5>0),"TRIM","HOLD"))) -> HOLD
A6: ='Data Input'!A58 -> IWM | B6: ='Data Input'!B58 -> US Eq | C6: ='Data Input'!C58 -> ETF | D6: =IFERROR('Data Input'!E58,0) | E6: =IFERROR('Data Input'!H58,0) | F6: =IFERROR('Data Input'!V58,0) | G6: =IFERROR('Data Input'!W58,0) | H6: =IFERROR('Data Input'!J58,0) | I6: =IFERROR('Data Input'!I58,0) | J6: =IFERROR('Data Input'!M58,0) | K6: =IFERROR('Data Input'!N58,0) | L6: =IFERROR('Data Input'!O58,0) | M6: =IFERROR('Data Input'!P58,0) | N6: =IFERROR(IF('Data Input'!Q58<>"",'Data Input'!Q58,MIN(100,MAX(0,ROUND(50+(J6*0.4+K6*0.3+L6*0.2+M6*0.1)*200,0)))),0) -> 0 | O6: =IF('Data Input'!S58<>"",'Data Input'!S58,IF(N6>=70,"BUY",IF(N6>=50,"HOLD","SELL"))) -> SELL | P6: =RANK(N6,N$4:N$27,0) -> 1 | Q6: ='Data Input'!AD58 -> 0.04 | R6: ='Data Input'!AE58 -> 0.04 | S6: =R6-Q6 -> 0 | T6: =IF(ABS(S6)>'Data Input'!$B$9,"REBALANCE",IF(AND(O6="BUY",S6<0),"ADD",IF(AND(O6="SELL",S6>0),"TRIM","HOLD"))) -> HOLD
A7: ='Data Input'!A59 -> EFA | B7: ='Data Input'!B59 -> Intl | C7: ='Data Input'!C59 -> ETF | D7: =IFERROR('Data Input'!E59,0) | E7: =IFERROR('Data Input'!H59,0) | F7: =IFERROR('Data Input'!V59,0) | G7: =IFERROR('Data Input'!W59,0) | H7: =IFERROR('Data Input'!J59,0) | I7: =IFERROR('Data Input'!I59,0) | J7: =IFERROR('Data Input'!M59,0) | K7: =IFERROR('Data Input'!N59,0) | L7: =IFERROR('Data Input'!O59,0) | M7: =IFERROR('Data Input'!P59,0) | N7: =IFERROR(IF('Data Input'!Q59<>"",'Data Input'!Q59,MIN(100,MAX(0,ROUND(50+(J7*0.4+K7*0.3+L7*0.2+M7*0.1)*200,0)))),0) -> 0 | O7: =IF('Data Input'!S59<>"",'Data Input'!S59,IF(N7>=70,"BUY",IF(N7>=50,"HOLD","SELL"))) -> SELL | P7: =RANK(N7,N$4:N$27,0) -> 1 | Q7: ='Data Input'!AD59 -> 0.05 | R7: ='Data Input'!AE59 -> 0.06 | S7: =R7-Q7 -> 0.01 | T7: =IF(ABS(S7)>'Data Input'!$B$9,"REBALANCE",IF(AND(O7="BUY",S7<0),"ADD",IF(AND(O7="SELL",S7>0),"TRIM","HOLD"))) -> TRIM
A8: ='Data Input'!A60 -> EEM | B8: ='Data Input'!B60 -> Intl | C8: ='Data Input'!C60 -> ETF | D8: =IFERROR('Data Input'!E60,0) | E8: =IFERROR('Data Input'!H60,0) | F8: =IFERROR('Data Input'!V60,0) | G8: =IFERROR('Data Input'!W60,0) | H8: =IFERROR('Data Input'!J60,0) | I8: =IFERROR('Data Input'!I60,0) | J8: =IFERROR('Data Input'!M60,0) | K8: =IFERROR('Data Input'!N60,0) | L8: =IFERROR('Data Input'!O60,0) | M8: =IFERROR('Data Input'!P60,0) | N8: =IFERROR(IF('Data Input'!Q60<>"",'Data Input'!Q60,MIN(100,MAX(0,ROUND(50+(J8*0.4+K8*0.3+L8*0.2+M8*0.1)*200,0)))),0) -> 0 | O8: =IF('Data Input'!S60<>"",'Data Input'!S60,IF(N8>=70,"BUY",IF(N8>=50,"HOLD","SELL"))) -> SELL | P8: =RANK(N8,N$4:N$27,0) -> 1 | Q8: ='Data Input'!AD60 -> 0.03 | R8: ='Data Input'!AE60 -> 0.025 | S8: =R8-Q8 -> -0.005 | T8: =IF(ABS(S8)>'Data Input'!$B$9,"REBALANCE",IF(AND(O8="BUY",S8<0),"ADD",IF(AND(O8="SELL",S8>0),"TRIM","HOLD"))) -> HOLD
A9: ='Data Input'!A61 -> AGG | B9: ='Data Input'!B61 -> Bond | C9: ='Data Input'!C61 -> ETF | D9: =IFERROR('Data Input'!E61,0) | E9: =IFERROR('Data Input'!H61,0) | F9: =IFERROR('Data Input'!V61,0) | G9: =IFERROR('Data Input'!W61,0) | H9: =IFERROR('Data Input'!J61,0) | I9: =IFERROR('Data Input'!I61,0) | J9: =IFERROR('Data Input'!M61,0) | K9: =IFERROR('Data Input'!N61,0) | L9: =IFERROR('Data Input'!O61,0) | M9: =IFERROR('Data Input'!P61,0) | N9: =IFERROR(IF('Data Input'!Q61<>"",'Data Input'!Q61,MIN(100,MAX(0,ROUND(50+(J9*0.4+K9*0.3+L9*0.2+M9*0.1)*200,0)))),0) -> 0 | O9: =IF('Data Input'!S61<>"",'Data Input'!S61,IF(N9>=70,"BUY",IF(N9>=50,"HOLD","SELL"))) -> SELL | P9: =RANK(N9,N$4:N$27,0) -> 1 | Q9: ='Data Input'!AD61 -> 0.1 | R9: ='Data Input'!AE61 -> 0.1 | S9: =R9-Q9 -> 0 | T9: =IF(ABS(S9)>'Data Input'!$B$9,"REBALANCE",IF(AND(O9="BUY",S9<0),"ADD",IF(AND(O9="SELL",S9>0),"TRIM","HOLD"))) -> HOLD
A10: ='Data Input'!A62 -> TLT | B10: ='Data Input'!B62 -> Bond | C10: ='Data Input'!C62 -> ETF | D10: =IFERROR('Data Input'!E62,0) | E10: =IFERROR('Data Input'!H62,0) | F10: =IFERROR('Data Input'!V62,0) | G10: =IFERROR('Data Input'!W62,0) | H10: =IFERROR('Data Input'!J62,0) | I10: =IFERROR('Data Input'!I62,0) | J10: =IFERROR('Data Input'!M62,0) | K10: =IFERROR('Data Input'!N62,0) | L10: =IFERROR('Data Input'!O62,0) | M10: =IFERROR('Data Input'!P62,0) | N10: =IFERROR(IF('Data Input'!Q62<>"",'Data Input'!Q62,MIN(100,MAX(0,ROUND(50+(J10*0.4+K10*0.3+L10*0.2+M10*0.1)*200,0)))),0) -> 0 | O10: =IF('Data Input'!S62<>"",'Data Input'!S62,IF(N10>=70,"BUY",IF(N10>=50,"HOLD","SELL"))) -> SELL | P10: =RANK(N10,N$4:N$27,0) -> 1 | Q10: ='Data Input'!AD62 -> 0.05 | R10: ='Data Input'!AE62 -> 0.06 | S10: =R10-Q10 -> 0.01 | T10: =IF(ABS(S10)>'Data Input'!$B$9,"REBALANCE",IF(AND(O10="BUY",S10<0),"ADD",IF(AND(O10="SELL",S10>0),"TRIM","HOLD"))) -> TRIM
A11: ='Data Input'!A63 -> GLD | B11: ='Data Input'!B63 -> Alt | C11: ='Data Input'!C63 -> ETF | D11: =IFERROR('Data Input'!E63,0) | E11: =IFERROR('Data Input'!H63,0) | F11: =IFERROR('Data Input'!V63,0) | G11: =IFERROR('Data Input'!W63,0) | H11: =IFERROR('Data Input'!J63,0) | I11: =IFERROR('Data Input'!I63,0) | J11: =IFERROR('Data Input'!M63,0) | K11: =IFERROR('Data Input'!N63,0) | L11: =IFERROR('Data Input'!O63,0) | M11: =IFERROR('Data Input'!P63,0) | N11: =IFERROR(IF('Data Input'!Q63<>"",'Data Input'!Q63,MIN(100,MAX(0,ROUND(50+(J11*0.4+K11*0.3+L11*0.2+M11*0.1)*200,0)))),0) -> 0 | O11: =IF('Data Input'!S63<>"",'Data Input'!S63,IF(N11>=70,"BUY",IF(N11>=50,"HOLD","SELL"))) -> SELL | P11: =RANK(N11,N$4:N$27,0) -> 1 | Q11: ='Data Input'!AD63 -> 0.08 | R11: ='Data Input'!AE63 -> 0.075 | S11: =R11-Q11 -> -0.005 | T11: =IF(ABS(S11)>'Data Input'!$B$9,"REBALANCE",IF(AND(O11="BUY",S11<0),"ADD",IF(AND(O11="SELL",S11>0),"TRIM","HOLD"))) -> HOLD
A12: ='Data Input'!A64 -> VNQ | B12: ='Data Input'!B64 -> REIT | C12: ='Data Input'!C64 -> ETF | D12: =IFERROR('Data Input'!E64,0) | E12: =IFERROR('Data Input'!H64,0) | F12: =IFERROR('Data Input'!V64,0) | G12: =IFERROR('Data Input'!W64,0) | H12: =IFERROR('Data Input'!J64,0) | I12: =IFERROR('Data Input'!I64,0) | J12: =IFERROR('Data Input'!M64,0) | K12: =IFERROR('Data Input'!N64,0) | L12: =IFERROR('Data Input'!O64,0) | M12: =IFERROR('Data Input'!P64,0) | N12: =IFERROR(IF('Data Input'!Q64<>"",'Data Input'!Q64,MIN(100,MAX(0,ROUND(50+(J12*0.4+K12*0.3+L12*0.2+M12*0.1)*200,0)))),0) -> 0 | O12: =IF('Data Input'!S64<>"",'Data Input'!S64,IF(N12>=70,"BUY",IF(N12>=50,"HOLD","SELL"))) -> SELL | P12: =RANK(N12,N$4:N$27,0) -> 1 | Q12: ='Data Input'!AD64 -> 0.05 | R12: ='Data Input'!AE64 -> 0.05 | S12: =R12-Q12 -> 0 | T12: =IF(ABS(S12)>'Data Input'!$B$9,"REBALANCE",IF(AND(O12="BUY",S12<0),"ADD",IF(AND(O12="SELL",S12>0),"TRIM","HOLD"))) -> HOLD
A13: ='Data Input'!A65 -> XLK | B13: ='Data Input'!B65 -> US Eq | C13: ='Data Input'!C65 -> ETF | D13: =IFERROR('Data Input'!E65,0) | E13: =IFERROR('Data Input'!H65,0) | F13: =IFERROR('Data Input'!V65,0) | G13: =IFERROR('Data Input'!W65,0) | H13: =IFERROR('Data Input'!J65,0) | I13: =IFERROR('Data Input'!I65,0) | J13: =IFERROR('Data Input'!M65,0) | K13: =IFERROR('Data Input'!N65,0) | L13: =IFERROR('Data Input'!O65,0) | M13: =IFERROR('Data Input'!P65,0) | N13: =IFERROR(IF('Data Input'!Q65<>"",'Data Input'!Q65,MIN(100,MAX(0,ROUND(50+(J13*0.4+K13*0.3+L13*0.2+M13*0.1)*200,0)))),0) -> 0 | O13: =IF('Data Input'!S65<>"",'Data Input'!S65,IF(N13>=70,"BUY",IF(N13>=50,"HOLD","SELL"))) -> SELL | P13: =RANK(N13,N$4:N$27,0) -> 1 | Q13: ='Data Input'!AD65 -> 0.08 | R13: ='Data Input'!AE65 -> 0.09 | S13: =R13-Q13 -> 0.01 | T13: =IF(ABS(S13)>'Data Input'!$B$9,"REBALANCE",IF(AND(O13="BUY",S13<0),"ADD",IF(AND(O13="SELL",S13>0),"TRIM","HOLD"))) -> TRIM
A14: ='Data Input'!A66 -> XLV | B14: ='Data Input'!B66 -> US Eq | C14: ='Data Input'!C66 -> ETF | D14: =IFERROR('Data Input'!E66,0) | E14: =IFERROR('Data Input'!H66,0) | F14: =IFERROR('Data Input'!V66,0) | G14: =IFERROR('Data Input'!W66,0) | H14: =IFERROR('Data Input'!J66,0) | I14: =IFERROR('Data Input'!I66,0) | J14: =IFERROR('Data Input'!M66,0) | K14: =IFERROR('Data Input'!N66,0) | L14: =IFERROR('Data Input'!O66,0) | M14: =IFERROR('Data Input'!P66,0) | N14: =IFERROR(IF('Data Input'!Q66<>"",'Data Input'!Q66,MIN(100,MAX(0,ROUND(50+(J14*0.4+K14*0.3+L14*0.2+M14*0.1)*200,0)))),0) -> 0 | O14: =IF('Data Input'!S66<>"",'Data Input'!S66,IF(N14>=70,"BUY",IF(N14>=50,"HOLD","SELL"))) -> SELL | P14: =RANK(N14,N$4:N$27,0) -> 1 | Q14: ='Data Input'!AD66 -> 0.04 | R14: ='Data Input'!AE66 -> 0.035 | S14: =R14-Q14 -> -0.005 | T14: =IF(ABS(S14)>'Data Input'!$B$9,"REBALANCE",IF(AND(O14="BUY",S14<0),"ADD",IF(AND(O14="SELL",S14>0),"TRIM","HOLD"))) -> HOLD
A15: ='Data Input'!A67 -> XLE | B15: ='Data Input'!B67 -> US Eq | C15: ='Data Input'!C67 -> ETF | D15: =IFERROR('Data Input'!E67,0) | E15: =IFERROR('Data Input'!H67,0) | F15: =IFERROR('Data Input'!V67,0) | G15: =IFERROR('Data Input'!W67,0) | H15: =IFERROR('Data Input'!J67,0) | I15: =IFERROR('Data Input'!I67,0) | J15: =IFERROR('Data Input'!M67,0) | K15: =IFERROR('Data Input'!N67,0) | L15: =IFERROR('Data Input'!O67,0) | M15: =IFERROR('Data Input'!P67,0) | N15: =IFERROR(IF('Data Input'!Q67<>"",'Data Input'!Q67,MIN(100,MAX(0,ROUND(50+(J15*0.4+K15*0.3+L15*0.2+M15*0.1)*200,0)))),0) -> 0 | O15: =IF('Data Input'!S67<>"",'Data Input'!S67,IF(N15>=70,"BUY",IF(N15>=50,"HOLD","SELL"))) -> SELL | P15: =RANK(N15,N$4:N$27,0) -> 1 | Q15: ='Data Input'!AD67 -> 0.03 | R15: ='Data Input'!AE67 -> 0.03 | S15: =R15-Q15 -> 0 | T15: =IF(ABS(S15)>'Data Input'!$B$9,"REBALANCE",IF(AND(O15="BUY",S15<0),"ADD",IF(AND(O15="SELL",S15>0),"TRIM","HOLD"))) -> HOLD
... A27: ='Data Input'!A79 -> PIMIX | B27: ='Data Input'!B79 -> Bond | C27: ='Data Input'!C79 -> MF | D27: =IFERROR('Data Input'!E79,0) | E27: =IFERROR('Data Input'!H79,0) | F27: =IFERROR('Data Input'!V79,0) | G27: =IFERROR('Data Input'!W79,0) | H27: =IFERROR('Data Input'!J79,0) | I27: =IFERROR('Data Input'!I79,0) | J27: =IFERROR('Data Input'!M79,0) | K27: =IFERROR('Data Input'!N79,0) | L27: =IFERROR('Data Input'!O79,0) | M27: =IFERROR('Data Input'!P79,0) | N27: =IFERROR(IF('Data Input'!Q79<>"",'Data Input'!Q79,MIN(100,MAX(0,ROUND(50+(J27*0.4+K27*0.3+L27*0.2+M27*0.1)*200,0)))),0) -> 0 | O27: =IF('Data Input'!S79<>"",'Data Input'!S79,IF(N27>=70,"BUY",IF(N27>=50,"HOLD","SELL"))) -> SELL | P27: =RANK(N27,N$4:N$27,0) -> 1 | Q27: ='Data Input'!AD79 -> 0 | R27: ='Data Input'!AE79 -> 0 | S27: =R27-Q27 -> 0 | T27: =IF(ABS(S27)>'Data Input'!$B$9,"REBALANCE",IF(AND(O27="BUY",S27<0),"ADD",IF(AND(O27="SELL",S27>0),"TRIM","HOLD"))) -> HOLD
A28: TOTALS | Q28: =SUM(Q4:Q27) -> 1 | R28: =SUM(R4:R27) -> 1.04
A29: AVERAGES | D29: =IFERROR(AVERAGE(D4:D27),0) -> 0 | E29: =IFERROR(AVERAGE(E4:E27),0) -> 0 | F29: =IFERROR(AVERAGE(F4:F27),0) -> 0 | H29: =IFERROR(AVERAGE(H4:H27),0) -> 0 | N29: =IFERROR(AVERAGE(N4:N27),0) -> 0
A30: SIGNAL COUNTS | O30: =COUNTIF(O4:O27,"BUY")&" BUY / "&COUNTIF(O4:O27,"HOLD")&" HOLD / "&COUNTIF(O4:O27,"SELL")&" SELL" -> 0 BUY / 0 HOLD / 24 SELL

Sheet Dashboard
A1: PORTFOLIO DASHBOARD — All values computed from Asset Analysis & Data Input
A3: PORTFOLIO METRICS
A4: Portfolio Value | C4: Weighted Return | E4: Weighted Vol | G4: Sharpe | I4: Avg Max DD | K4: Avg Beta | M4: # Assets | O4: # BUY Signals
A5: ='Data Input'!B7 -> 0.16 | C5: =SUMPRODUCT('Asset Analysis'!R4:R27,'Asset Analysis'!D4:D27) -> 0 | E5: =SUMPRODUCT('Asset Analysis'!R4:R27,'Asset Analysis'!E4:E27) -> 0 | G5: =IF(E5=0,0,(C5-'Data Input'!B4)/E5) -> 0 | I5: =IFERROR(AVERAGE('Asset Analysis'!I4:I27),0) -> 0 | K5: =SUMPRODUCT('Asset Analysis'!R4:R27,'Asset Analysis'!H4:H27) -> 0 | M5: =COUNTA('Asset Analysis'!A4:A27) -> 24 | O5: =COUNTIF('Asset Analysis'!O4:O27,"BUY") -> 0
A8: FSM MODEL STATUS
A9: Bullish % | B9: ='Data Input'!B84 -> 0
A10: FSM Signal | B10: ='Data Input'!B85 -> RISK OFF
A12: CASH TRIGGERS
A13: Trigger | B13: Current | C13: Threshold | D13: Status
A14: MMPR50 | B14: ='Data Input'!B88 -> 0 | C14: ='Data Input'!B23 -> 0.04 | D14: ='Data Input'!C88 -> ⚠ TRIGGERED
A15: MMPR70 | B15: ='Data Input'!B89 -> 0 | C15: ='Data Input'!B24 -> 0.005 | D15: ='Data Input'!C89 -> ⚠ TRIGGERED
A16: PR4050 | B16: ='Data Input'!B90 -> 0 | C16: ='Data Input'!B25 | D16: ='Data Input'!C90 -> ⚠ TRIGGERED
A17: PR4080 | B17: ='Data Input'!B91 -> 0 | C17: ='Data Input'!B26 | D17: ='Data Input'!C91 -> ⚠ TRIGGERED
A18: ='Data Input'!B92 -> ⚠ CASH TRIGGER ACTIVE

Sheet Signal Engine
A1: MULTI-FACTOR SIGNAL ENGINE — All scores are formulas
A3: WEIGHTS (from Data Input)
A4: Trend | B4: ='Data Input'!B29 -> 50 | C4: Technical | D4: ='Data Input'!B30 -> 0 | E4: Fundamental | F4: ='Data Input'!B31 -> 0 | G4: DWA | H4: ='Data Input'!B32 -> 0
A6: SIGNAL THRESHOLDS
A7: STRONG BUY | B7: ≥70 | C7: 3+ factors ≥60 | D7: Overweight aggressively
A8: BUY | B8: ≥60 | C8: 2+ factors ≥60 | D8: Add / Initiate
A9: HOLD | B9: 45-59 | C9: Mixed | D9: Maintain weight
A10: SELL | B10: <45 | C10: ≤1 factor ≥60 | D10: Trim / Reduce
A11: STRONG SELL | B11: <35 | C11: 0-1 factors | D11: Exit / Replace w/ buffered
A14: COMPOSITE SIGNALS
A15: Ticker | B15: Trend | C15: Technical | D15: Fundamental | E15: DWA | F15: Composite | G15: Signal | H15: Conviction | I15: Factors ≥60 | J15: Divergence
A16: ='Data Input'!A56 -> SPY | B16: ='Data Input'!Z56 -> 0 | C16: ='Data Input'!AA56 -> 0 | D16: ='Data Input'!AB56 -> 0 | E16: ='Asset Analysis'!N4 -> 0 | F16: ='Data Input'!AC56 -> 0 | G16: =IF(AND(F16>=70,I16>=3),"STRONG BUY",IF(AND(F16>=60,I16>=2),"BUY",IF(AND(F16<35),"STRONG SELL",IF(AND(F16<45,I16<=1),"SELL","HOLD")))) -> STRONG SELL | H16: =IF(OR(G16="STRONG BUY",G16="STRONG SELL"),"HIGH",IF(OR(G16="BUY",G16="SELL"),"MEDIUM",IF(G16="HOLD","NEUTRAL","LOW"))) -> HIGH | I16: =IF(B16>=60,1,0)+IF(C16>=60,1,0)+IF(D16>=60,1,0)+IF(E16>=60,1,0) -> 0 | J16: =IF((MAX(B16:E16)-MIN(B16:E16))>35,"⚠ DIVERGENCE","")
A17: ='Data Input'!A57 -> QQQ | B17: ='Data Input'!Z57 -> 0 | C17: ='Data Input'!AA57 -> 0 | D17: ='Data Input'!AB57 -> 0 | E17: ='Asset Analysis'!N5 -> 0 | F17: ='Data Input'!AC57 -> 0 | G17: =IF(AND(F17>=70,I17>=3),"STRONG BUY",IF(AND(F17>=60,I17>=2),"BUY",IF(AND(F17<35),"STRONG SELL",IF(AND(F17<45,I17<=1),"SELL","HOLD")))) -> STRONG SELL | H17: =IF(OR(G17="STRONG BUY",G17="STRONG SELL"),"HIGH",IF(OR(G17="BUY",G17="SELL"),"MEDIUM",IF(G17="HOLD","NEUTRAL","LOW"))) -> HIGH | I17: =IF(B17>=60,1,0)+IF(C17>=60,1,0)+IF(D17>=60,1,0)+IF(E17>=60,1,0) -> 0 | J17: =IF((MAX(B17:E17)-MIN(B17:E17))>35,"⚠ DIVERGENCE","")
A18: ='Data Input'!A58 -> IWM | B18: ='Data Input'!Z58 -> 0 | C18: ='Data Input'!AA58 -> 0 | D18: ='Data Input'!AB58 -> 0 | E18: ='Asset Analysis'!N6 -> 0 | F18: ='Data Input'!AC58 -> 0 | G18: =IF(AND(F18>=70,I18>=3),"STRONG BUY",IF(AND(F18>=60,I18>=2),"BUY",IF(AND(F18<35),"STRONG SELL",IF(AND(F18<45,I18<=1),"SELL","HOLD")))) -> STRONG SELL | H18: =IF(OR(G18="STRONG BUY",G18="STRONG SELL"),"HIGH",IF(OR(G18="BUY",G18="SELL"),"MEDIUM",IF(G18="HOLD","NEUTRAL","LOW"))) -> HIGH | I18: =IF(B18>=60,1,0)+IF(C18>=60,1,0)+IF(D18>=60,1,0)+IF(E18>=60,1,0) -> 0 | J18: =IF((MAX(B18:E18)-MIN(B18:E18))>35,"⚠ DIVERGENCE","")
A19: ='Data Input'!A59 -> EFA | B19: ='Data Input'!Z59 -> 0 | C19: ='Data Input'!AA59 -> 0 | D19: ='Data Input'!AB59 -> 0 | E19: ='Asset Analysis'!N7 -> 0 | F19: ='Data Input'!AC59 -> 0 | G19: =IF(AND(F19>=70,I19>=3),"STRONG BUY",IF(AND(F19>=60,I19>=2),"BUY",IF(AND(F19<35),"STRONG SELL",IF(AND(F19<45,I19<=1),"SELL","HOLD")))) -> STRONG SELL | H19: =IF(OR(G19="STRONG BUY",G19="STRONG SELL"),"HIGH",IF(OR(G19="BUY",G19="SELL"),"MEDIUM",IF(G19="HOLD","NEUTRAL","LOW"))) -> HIGH | I19: =IF(B19>=60,1,0)+IF(C19>=60,1,0)+IF(D19>=60,1,0)+IF(E19>=60,1,0) -> 0 | J19: =IF((MAX(B19:E19)-MIN(B19:E19))>35,"⚠ DIVERGENCE","")
A20: ='Data Input'!A60 -> EEM | B20: ='Data Input'!Z60 -> 0 | C20: ='Data Input'!AA60 -> 0 | D20: ='Data Input'!AB60 -> 0 | E20: ='Asset Analysis'!N8 -> 0 | F20: ='Data Input'!AC60 -> 0 | G20: =IF(AND(F20>=70,I20>=3),"STRONG BUY",IF(AND(F20>=60,I20>=2),"BUY",IF(AND(F20<35),"STRONG SELL",IF(AND(F20<45,I20<=1),"SELL","HOLD")))) -> STRONG SELL | H20: =IF(OR(G20="STRONG BUY",G20="STRONG SELL"),"HIGH",IF(OR(G20="BUY",G20="SELL"),"MEDIUM",IF(G20="HOLD","NEUTRAL","LOW"))) -> HIGH | I20: =IF(B20>=60,1,0)+IF(C20>=60,1,0)+IF(D20>=60,1,0)+IF(E20>=60,1,0) -> 0 | J20: =IF((MAX(B20:E20)-MIN(B20:E20))>35,"⚠ DIVERGENCE","")
A21: ='Data Input'!A61 -> AGG | B21: ='Data Input'!Z61 -> 0 | C21: ='Data Input'!AA61 -> 0 | D21: ='Data Input'!AB61 -> 0 | E21: ='Asset Analysis'!N9 -> 0 | F21: ='Data Input'!AC61 -> 0 | G21: =IF(AND(F21>=70,I21>=3),"STRONG BUY",IF(AND(F21>=60,I21>=2),"BUY",IF(AND(F21<35),"STRONG SELL",IF(AND(F21<45,I21<=1),"SELL","HOLD")))) -> STRONG SELL | H21: =IF(OR(G21="STRONG BUY",G21="STRONG SELL"),"HIGH",IF(OR(G21="BUY",G21="SELL"),"MEDIUM",IF(G21="HOLD","NEUTRAL","LOW"))) -> HIGH | I21: =IF(B21>=60,1,0)+IF(C21>=60,1,0)+IF(D21>=60,1,0)+IF(E21>=60,1,0) -> 0 | J21: =IF((MAX(B21:E21)-MIN(B21:E21))>35,"⚠ DIVERGENCE","")
A22: ='Data Input'!A62 -> TLT | B22: ='Data Input'!Z62 -> 0 | C22: ='Data Input'!AA62 -> 0 | D22: ='Data Input'!AB62 -> 0 | E22: ='Asset Analysis'!N10 -> 0 | F22: ='Data Input'!AC62 -> 0 | G22: =IF(AND(F22>=70,I22>=3),"STRONG BUY",IF(AND(F22>=60,I22>=2),"BUY",IF(AND(F22<35),"STRONG SELL",IF(AND(F22<45,I22<=1),"SELL","HOLD")))) -> STRONG SELL | H22: =IF(OR(G22="STRONG BUY",G22="STRONG SELL"),"HIGH",IF(OR(G22="BUY",G22="SELL"),"MEDIUM",IF(G22="HOLD","NEUTRAL","LOW"))) -> HIGH | I22: =IF(B22>=60,1,0)+IF(C22>=60,1,0)+IF(D22>=60,1,0)+IF(E22>=60,1,0) -> 0 | J22: =IF((MAX(B22:E22)-MIN(B22:E22))>35,"⚠ DIVERGENCE","")
A23: ='Data Input'!A63 -> GLD | B23: ='Data Input'!Z63 -> 0 | C23: ='Data Input'!AA63 -> 0 | D23: ='Data Input'!AB63 -> 0 | E23: ='Asset Analysis'!N11 -> 0 | F23: ='Data Input'!AC63 -> 0 | G23: =IF(AND(F23>=70,I23>=3),"STRONG BUY",IF(AND(F23>=60,I23>=2),"BUY",IF(AND(F23<35),"STRONG SELL",IF(AND(F23<45,I23<=1),"SELL","HOLD")))) -> STRONG SELL | H23: =IF(OR(G23="STRONG BUY",G23="STRONG SELL"),"HIGH",IF(OR(G23="BUY",G23="SELL"),"MEDIUM",IF(G23="HOLD","NEUTRAL","LOW"))) -> HIGH | I23: =IF(B23>=60,1,0)+IF(C23>=60,1,0)+IF(D23>=60,1,0)+IF(E23>=60,1,0) -> 0 | J23: =IF((MAX(B23:E23)-MIN(B23:E23))>35,"⚠ DIVERGENCE","")
A24: ='Data Input'!A64 -> VNQ | B24: ='Data Input'!Z64 -> 0 | C24: ='Data Input'!AA64 -> 0 | D24: ='Data Input'!AB64 -> 0 | E24: ='Asset Analysis'!N12 -> 0 | F24: ='Data Input'!AC64 -> 0 | G24: =IF(AND(F24>=70,I24>=3),"STRONG BUY",IF(AND(F24>=60,I24>=2),"BUY",IF(AND(F24<35),"STRONG SELL",IF(AND(F24<45,I24<=1),"SELL","HOLD")))) -> STRONG SELL | H24: =IF(OR(G24="STRONG BUY",G24="STRONG SELL"),"HIGH",IF(OR(G24="BUY",G24="SELL"),"MEDIUM",IF(G24="HOLD","NEUTRAL","LOW"))) -> HIGH | I24: =IF(B24>=60,1,0)+IF(C24>=60,1,0)+IF(D24>=60,1,0)+IF(E24>=60,1,0) -> 0 | J24: =IF((MAX(B24:E24)-MIN(B24:E24))>35,"⚠ DIVERGENCE","")
A25: ='Data Input'!A65 -> XLK | B25: ='Data Input'!Z65 -> 0 | C25: ='Data Input'!AA65 -> 0 | D25: ='Data Input'!AB65 -> 0 | E25: ='Asset Analysis'!N13 -> 0 | F25: ='Data Input'!AC65 -> 0 | G25: =IF(AND(F25>=70,I25>=3),"STRONG BUY",IF(AND(F25>=60,I25>=2),"BUY",IF(AND(F25<35),"STRONG SELL",IF(AND(F25<45,I25<=1),"SELL","HOLD")))) -> STRONG SELL | H25: =IF(OR(G25="STRONG BUY",G25="STRONG SELL"),"HIGH",IF(OR(G25="BUY",G25="SELL"),"MEDIUM",IF(G25="HOLD","NEUTRAL","LOW"))) -> HIGH | I25: =IF(B25>=60,1,0)+IF(C25>=60,1,0)+IF(D25>=60,1,0)+IF(E25>=60,1,0) -> 0 | J25: =IF((MAX(B25:E25)-MIN(B25:E25))>35,"⚠ DIVERGENCE","")
A26: ='Data Input'!A66 -> XLV | B26: ='Data Input'!Z66 -> 0 | C26: ='Data Input'!AA66 -> 0 | D26: ='Data Input'!AB66 -> 0 | E26: ='Asset Analysis'!N14 -> 0 | F26: ='Data Input'!AC66 -> 0 | G26: =IF(AND(F26>=70,I26>=3),"STRONG BUY",IF(AND(F26>=60,I26>=2),"BUY",IF(AND(F26<35),"STRONG SELL",IF(AND(F26<45,I26<=1),"SELL","HOLD")))) -> STRONG SELL | H26: =IF(OR(G26="STRONG BUY",G26="STRONG SELL"),"HIGH",IF(OR(G26="BUY",G26="SELL"),"MEDIUM",IF(G26="HOLD","NEUTRAL","LOW"))) -> HIGH | I26: =IF(B26>=60,1,0)+IF(C26>=60,1,0)+IF(D26>=60,1,0)+IF(E26>=60,1,0) -> 0 | J26: =IF((MAX(B26:E26)-MIN(B26:E26))>35,"⚠ DIVERGENCE","")
A27: ='Data Input'!A67 -> XLE | B27: ='Data Input'!Z67 -> 0 | C27: ='Data Input'!AA67 -> 0 | D27: ='Data Input'!AB67 -> 0 | E27: ='Asset Analysis'!N15 -> 0 | F27: ='Data Input'!AC67 -> 0 | G27: =IF(AND(F27>=70,I27>=3),"STRONG BUY",IF(AND(F27>=60,I27>=2),"BUY",IF(AND(F27<35),"STRONG SELL",IF(AND(F27<45,I27<=1),"SELL","HOLD")))) -> STRONG SELL | H27: =IF(OR(G27="STRONG BUY",G27="STRONG SELL"),"HIGH",IF(OR(G27="BUY",G27="SELL"),"MEDIUM",IF(G27="HOLD","NEUTRAL","LOW"))) -> HIGH | I27: =IF(B27>=60,1,0)+IF(C27>=60,1,0)+IF(D27>=60,1,0)+IF(E27>=60,1,0) -> 0 | J27: =IF((MAX(B27:E27)-MIN(B27:E27))>35,"⚠ DIVERGENCE","")
... A39: ='Data Input'!A79 -> PIMIX | B39: ='Data Input'!Z79 -> 0 | C39: ='Data Input'!AA79 -> 0 | D39: ='Data Input'!AB79 -> 0 | E39: ='Asset Analysis'!N27 -> 0 | F39: ='Data Input'!AC79 -> 0 | G39: =IF(AND(F39>=70,I39>=3),"STRONG BUY",IF(AND(F39>=60,I39>=2),"BUY",IF(AND(F39<35),"STRONG SELL",IF(AND(F39<45,I39<=1),"SELL","HOLD")))) -> STRONG SELL | H39: =IF(OR(G39="STRONG BUY",G39="STRONG SELL"),"HIGH",IF(OR(G39="BUY",G39="SELL"),"MEDIUM",IF(G39="HOLD","NEUTRAL","LOW"))) -> HIGH | I39: =IF(B39>=60,1,0)+IF(C39>=60,1,0)+IF(D39>=60,1,0)+IF(E39>=60,1,0) -> 0 | J39: =IF((MAX(B39:E39)-MIN(B39:E39))>35,"⚠ DIVERGENCE","")
A41: SUMMARY | F41: =AVERAGE(F16:F39) -> 0
A42: Buy Signals | F42: =COUNTIF(G16:G39,"*BUY*") -> 0
A43: Sell Signals | F43: =COUNTIF(G16:G39,"*SELL*") -> 24
A44: Divergences | F44: =COUNTIF(J16:J39,"*DIV*") -> 0

Sheet Buffered ETF Strategy
A1: BUFFERED ETF ALLOCATION — Regime score drives allocation (all formulas)
A3: REGIME SCORING ENGINE
A4: Component | B4: Input | C4: Score | D4: Max | E4: Logic
A5: Volatility (VIX Input) | B5: ='Data Input'!B21 -> 18 | C5: =IF(B5>30,25,IF(B5>25,22,IF(B5>20,18,IF(B5>15,12,6)))) -> 12 | D5: 25 | E5: VIX>30=25, >25=22, >20=18, >15=12, else 6
A6: FSM Regime | B6: =Dashboard!B10 -> RISK OFF | C6: =IF(B6="RISK OFF",25,IF(B6="DEFENSIVE",20,IF(B6="CAUTION",12,5))) -> 25 | D6: 25 | E6: RISK OFF=25, DEFENSIVE=20, CAUTION=12, else 5
A7: Cash Triggers Active | B7: =COUNTIF(Dashboard!D14:D17,"⚠ TRIGGERED") -> 4 | C7: =MIN(25,B7*7) -> 25 | D7: 25 | E7: 7 pts per trigger, max 25
A8: Trend (% in uptrend) | B8: =Dashboard!B9 -> 0 | C8: =IF(B8<0.3,25,IF(B8<0.4,20,IF(B8<0.5,15,IF(B8<0.6,8,3)))) -> 25 | D8: 25 | E8: <30%=25, <40%=20, <50%=15, <60%=8, else 3
A10: TOTAL REGIME SCORE | C10: =SUM(C5:C8) -> 87 | D10: 100
A11: URGENCY | C11: =IF(C10>=75,"MAXIMUM BUFFER",IF(C10>=55,"ELEVATED BUFFER",IF(C10>=35,"STANDARD BUFFER","MINIMAL / OPPORTUNISTIC"))) -> MAXIMUM BUFFER
C12: =IF(C10>=75,"IMMEDIATE",IF(C10>=55,"THIS WEEK",IF(C10>=35,"NEXT REBALANCE","MONITOR"))) -> IMMEDIATE
A13: TARGET ALLOCATION | B13: =IF(C10>=75,"25-35%",IF(C10>=55,"15-28%",IF(C10>=35,"8-20%","0-12%"))) -> 25-35%
A14: Min % | B14: =IF(C10>=75,0.25,IF(C10>=55,0.15,IF(C10>=35,0.08,0))) -> 0.25
A15: Target % | B15: =IF(C10>=75,0.3,IF(C10>=55,0.22,IF(C10>=35,0.15,0.08))) -> 0.3
A16: Max % | B16: =IF(C10>=75,0.35,IF(C10>=55,0.28,IF(C10>=35,0.2,0.12))) -> 0.35
A17: $ Target | B17: =B15*'Data Input'!B7 -> 0.048
A20: ALLOCATION SCALE
A21: Regime | B21: Score | C21: Allocation | D21: Products | E21: Urgency
A22: MINIMAL | B22: 0-34 | C22: 0-12% | D22: DDT/DDF (high caps), small BUFR | E22: MONITOR
A23: STANDARD | B23: 35-54 | C23: 8-20% | D23: BUFR core, DDSQ/DDNQ tactical | E23: NEXT REBALANCE
A24: ELEVATED | B24: 55-74 | C24: 15-28% | D24: BUFR+DDT, BUFS small cap | E24: THIS WEEK
A25: MAXIMUM | B25: 75-100 | C25: 25-35% | D25: BUFZ deep, DDF 15%, shift eq→buf | E25: IMMEDIATE
A28: PRODUCT UNIVERSE
A29: Ticker | B29: Name | C29: Provider | D29: Reference | E29: Buffer | F29: Period | G29: Type
A30: BUFR | B30: Laddered Moderate Buffer | C30: First Trust | D30: S&P 500 | E30: 15% | F30: 12-mo Ladder | G30: Buffer
A31: BUFZ | B31: Laddered Deep Buffer | C31: First Trust | D31: S&P 500 | E31: 5-30% | F31: 12-mo Ladder | G31: Deep Buffer
A32: BUFS | B32: Small Cap Moderate | C32: First Trust | D32: Russell 2000 | E32: 15% | F32: Quarterly | G32: Buffer
A33: BUFY | B33: Int'l Moderate | C33: First Trust | D33: MSCI EAFE | E33: 15% | F33: Quarterly | G33: Buffer
A34: DDT | B34: Dual Directional 10 | C34: Innovator | D34: S&P 500 | E34: 10% | F34: 1Y Monthly | G34: Dual Dir
A35: DDF | B35: Dual Directional 15 | C35: Innovator | D35: S&P 500 | E35: 15% | F35: 1Y Monthly | G35: Dual Dir
A36: DDSQ | B36: Quarterly DD (SPY) | C36: Innovator | D36: S&P 500 | E36: 5% | F36: 3M Quarterly | G36: Dual Dir
A37: DDNQ | B37: Quarterly DD (QQQ) | C37: Innovator | D37: Nasdaq-100 | E37: 5% | F37: 3M Quarterly | G37: Dual Dir
A40: INTEGRATION TRIGGERS
A41: Trigger | B41: Condition Met? | C41: Action | D41: Products
A42: FSM RISK OFF | B42: =IF(Dashboard!B10="RISK OFF","YES","NO") -> YES | C42: Max buffer 25-35% | D42: BUFZ+DDF
A43: FSM DEFENSIVE | B43: =IF(Dashboard!B10="DEFENSIVE","YES","NO") -> NO | C43: Elevated 15-28% | D43: BUFR+DDT
A44: MMPR50 Triggered | B44: =IF(Dashboard!D14="⚠ TRIGGERED","YES","NO") -> YES | C44: Buffer +5% | D44: BUFR priority
A45: PR4080 Triggered | B45: =IF(Dashboard!D17="⚠ TRIGGERED","YES","NO") -> YES | C45: Emergency: 15% eq→buffer | D45: BUFZ/BUFD deep
A46: Avg Composite ≤ 35 | B46: =IF(AVERAGE('Signal Engine'!F16:F39)<=35,"YES","NO") -> YES | C46: Replace sells w/ buffered | D46: BUFR/DDT
A47: VIX<15 + FULLY INVESTED | B47: =IF(AND(B5<15,Dashboard!B10="FULLY INVESTED"),"YES","NO") -> NO | C47: Optimal entry — lock high caps | D47: DDT/DDF ladder

Sheet Risk Management
A1: RISK MANAGEMENT — Metrics computed from portfolio data
A3: PORTFOLIO RISK METRICS
A4: Metric | B4: Value | C4: Threshold | D4: Status
A5: Wtd Portfolio Vol | B5: =Dashboard!E5 -> 0 | C5: 0.25 | D5: =IF(B5>C5,"⚠ HIGH","OK") -> OK
A6: VaR 95% Daily | B6: =B5*1.645/SQRT(252) -> 0 | C6: 0.025 | D6: =IF(B6>C6,"⚠ BREACH","OK") -> OK
A7: VaR 99% Daily | B7: =B5*2.326/SQRT(252) -> 0 | C7: 0.04 | D7: =IF(B7>C7,"⚠ BREACH","OK") -> OK
A8: CVaR 95% (est) | B8: =B6*1.4 -> 0 | C8: 0.035 | D8: =IF(B8>C8,"⚠ BREACH","OK") -> OK
A9: Portfolio Beta | B9: =Dashboard!K5 -> 0 | C9: 1 | D9: =IF(B9>C9,"⚠ HIGH","OK") -> OK
A10: Avg Max Drawdown | B10: =IFERROR(Dashboard!I5,0) -> 0 | C10: 0.2 | D10: =IF(B10>C10,"⚠ HIGH","OK") -> OK
A11: $ at Risk (95% daily) | B11: =B6*'Data Input'!B7 -> 0 | C11: =C6*'Data Input'!B7 -> 0.004 | D11: =IF(B11>C11,"⚠ BREACH","OK") -> OK
A14: STRESS TESTS
A15: Scenario | B15: Market Shock | C15: Est. Portfolio Impact | D15: $ Loss | E15: Recovery Est.
A16: Market Crash -20% | B16: -0.2 | C16: =B16*Dashboard!$K$5 -> 0 | D16: =C16*'Data Input'!$B$7 -> 0 | E16: =ROUND(ABS(C16)*1000,0)&" days" -> 0 days
A17: Rate Shock +200bp | B17: -0.08 | C17: =B17*Dashboard!$K$5 -> 0 | D17: =C17*'Data Input'!$B$7 -> 0 | E17: =ROUND(ABS(C17)*1000,0)&" days" -> 0 days
A18: Tech Correction -15% | B18: -0.15 | C18: =B18*Dashboard!$K$5 -> 0 | D18: =C18*'Data Input'!$B$7 -> 0 | E18: =ROUND(ABS(C18)*1000,0)&" days" -> 0 days
A19: Recession -12% | B19: -0.12 | C19: =B19*Dashboard!$K$5 -> 0 | D19: =C19*'Data Input'!$B$7 -> 0 | E19: =ROUND(ABS(C19)*1000,0)&" days" -> 0 days
A20: Flash Crash -10% | B20: -0.1 | C20: =B20*Dashboard!$K$5 -> 0 | D20: =C20*'Data Input'!$B$7 -> 0 | E20: =ROUND(ABS(C20)*1000,0)&" days" -> 0 days
A21: Pandemic -30% | B21: -0.3 | C21: =B21*Dashboard!$K$5 -> 0 | D21: =C21*'Data Input'!$B$7 -> 0 | E21: =ROUND(ABS(C21)*1000,0)&" days" -> 0 days
A24: HEDGING RECOMMENDATIONS
A25: Hedge | B25: Allocation | C25: Corr to SPY | D25: Crisis Alpha | E25: Need Level
A26: TAIL | B26: 3-5% | C26: -0.7 | D26: HIGH | E26: MEDIUM
A27: BTAL | B27: 3-7% | C27: -0.5 | D27: MEDIUM | E27: MEDIUM
A28: DBMF | B28: 5-10% | C28: -0.1 | D28: HIGH | E28: HIGH
A29: TLT | B29: 5-15% | C29: -0.3 | D29: MEDIUM | E29: LOW
A30: GLD | B30: 5-10% | C30: 0.05 | D30: MEDIUM | E30: MEDIUM
A31: BUFR/BUFZ | B31: 10-30% | C31: N/A | D31: HIGH | E31: See Buffered ETF tab

Sheet Rebalancing
A1: REBALANCING WORKFLOW — All drift/action computed from Asset Analysis
A3: Ticker | B3: Target% | C3: Current% | D3: Drift | E3: Band | F3: Breach? | G3: Signal | H3: Action | I3: Shares | J3: $ Amount | K3: Tax | L3: Priority
A4: ='Asset Analysis'!A4 -> SPY | B4: ='Asset Analysis'!Q4 -> 0.08 | C4: ='Asset Analysis'!R4 -> 0.09 | D4: =C4-B4 -> 0.01 | E4: ='Data Input'!$B$8 -> 100000 | F4: =IF(ABS(D4)>E4,"YES","NO") -> NO | G4: ='Asset Analysis'!O4 -> SELL | H4: =IF(F4="YES",IF(D4<0,"BUY","SELL"),IF(AND(G4="BUY",D4<0),"ADD",IF(AND(G4="SELL",D4>0),"TRIM","HOLD"))) -> TRIM | I4: =ROUND(J4/100,0) -> 0 | J4: =ABS(D4)*'Data Input'!$B$7 -> 0.0016 | K4: =IF(H4="SELL","Check TLH","N/A") -> N/A | L4: =IF(ABS(D4)>0.03,"HIGH",IF(ABS(D4)>0.015,"MEDIUM","LOW")) -> LOW
A5: ='Asset Analysis'!A5 -> QQQ | B5: ='Asset Analysis'!Q5 -> 0.07 | C5: ='Asset Analysis'!R5 -> 0.065 | D5: =C5-B5 -> -0.005 | E5: ='Data Input'!$B$8 -> 100000 | F5: =IF(ABS(D5)>E5,"YES","NO") -> NO | G5: ='Asset Analysis'!O5 -> SELL | H5: =IF(F5="YES",IF(D5<0,"BUY","SELL"),IF(AND(G5="BUY",D5<0),"ADD",IF(AND(G5="SELL",D5>0),"TRIM","HOLD"))) -> HOLD | I5: =ROUND(J5/100,0) -> 0 | J5: =ABS(D5)*'Data Input'!$B$7 -> 0.0008 | K5: =IF(H5="SELL","Check TLH","N/A") -> N/A | L5: =IF(ABS(D5)>0.03,"HIGH",IF(ABS(D5)>0.015,"MEDIUM","LOW")) -> LOW
A6: ='Asset Analysis'!A6 -> IWM | B6: ='Asset Analysis'!Q6 -> 0.04 | C6: ='Asset Analysis'!R6 -> 0.04 | D6: =C6-B6 -> 0 | E6: ='Data Input'!$B$8 -> 100000 | F6: =IF(ABS(D6)>E6,"YES","NO") -> NO | G6: ='Asset Analysis'!O6 -> SELL | H6: =IF(F6="YES",IF(D6<0,"BUY","SELL"),IF(AND(G6="BUY",D6<0),"ADD",IF(AND(G6="SELL",D6>0),"TRIM","HOLD"))) -> HOLD | I6: =ROUND(J6/100,0) -> 0 | J6: =ABS(D6)*'Data Input'!$B$7 -> 0 | K6: =IF(H6="SELL","Check TLH","N/A") -> N/A | L6: =IF(ABS(D6)>0.03,"HIGH",IF(ABS(D6)>0.015,"MEDIUM","LOW")) -> LOW
A7: ='Asset Analysis'!A7 -> EFA | B7: ='Asset Analysis'!Q7 -> 0.05 | C7: ='Asset Analysis'!R7 -> 0.06 | D7: =C7-B7 -> 0.01 | E7: ='Data Input'!$B$8 -> 100000 | F7: =IF(ABS(D7)>E7,"YES","NO") -> NO | G7: ='Asset Analysis'!O7 -> SELL | H7: =IF(F7="YES",IF(D7<0,"BUY","SELL"),IF(AND(G7="BUY",D7<0),"ADD",IF(AND(G7="SELL",D7>0),"TRIM","HOLD"))) -> TRIM | I7: =ROUND(J7/100,0) -> 0 | J7: =ABS(D7)*'Data Input'!$B$7 -> 0.0016 | K7: =IF(H7="SELL","Check TLH","N/A") -> N/A | L7: =IF(ABS(D7)>0.03,"HIGH",IF(ABS(D7)>0.015,"MEDIUM","LOW")) -> LOW
A8: ='Asset Analysis'!A8 -> EEM | B8: ='Asset Analysis'!Q8 -> 0.03 | C8: ='Asset Analysis'!R8 -> 0.025 | D8: =C8-B8 -> -0.005 | E8: ='Data Input'!$B$8 -> 100000 | F8: =IF(ABS(D8)>E8,"YES","NO") -> NO | G8: ='Asset Analysis'!O8 -> SELL | H8: =IF(F8="YES",IF(D8<0,"BUY","SELL"),IF(AND(G8="BUY",D8<0),"ADD",IF(AND(G8="SELL",D8>0),"TRIM","HOLD"))) -> HOLD | I8: =ROUND(J8/100,0) -> 0 | J8: =ABS(D8)*'Data Input'!$B$7 -> 0.0008 | K8: =IF(H8="SELL","Check TLH","N/A") -> N/A | L8: =IF(ABS(D8)>0.03,"HIGH",IF(ABS(D8)>0.015,"MEDIUM","LOW")) -> LOW
A9: ='Asset Analysis'!A9 -> AGG | B9: ='Asset Analysis'!Q9 -> 0.1 | C9: ='Asset Analysis'!R9 -> 0.1 | D9: =C9-B9 -> 0 | E9: ='Data Input'!$B$8 -> 100000 | F9: =IF(ABS(D9)>E9,"YES","NO") -> NO | G9: ='Asset Analysis'!O9 -> SELL | H9: =IF(F9="YES",IF(D9<0,"BUY","SELL"),IF(AND(G9="BUY",D9<0),"ADD",IF(AND(G9="SELL",D9>0),"TRIM","HOLD"))) -> HOLD | I9: =ROUND(J9/100,0) -> 0 | J9: =ABS(D9)*'Data Input'!$B$7 -> 0 | K9: =IF(H9="SELL","Check TLH","N/A") -> N/A | L9: =IF(ABS(D9)>0.03,"HIGH",IF(ABS(D9)>0.015,"MEDIUM","LOW")) -> LOW
A10: ='Asset Analysis'!A10 -> TLT | B10: ='Asset Analysis'!Q10 -> 0.05 | C10: ='Asset Analysis'!R10 -> 0.06 | D10: =C10-B10 -> 0.01 | E10: ='Data Input'!$B$8 -> 100000 | F10: =IF(ABS(D10)>E10,"YES","NO") -> NO | G10: ='Asset Analysis'!O10 -> SELL | H10: =IF(F10="YES",IF(D10<0,"BUY","SELL"),IF(AND(G10="BUY",D10<0),"ADD",IF(AND(G10="SELL",D10>0),"TRIM","HOLD"))) -> TRIM | I10: =ROUND(J10/100,0) -> 0 | J10: =ABS(D10)*'Data Input'!$B$7 -> 0.0016 | K10: =IF(H10="SELL","Check TLH","N/A") -> N/A | L10: =IF(ABS(D10)>0.03,"HIGH",IF(ABS(D10)>0.015,"MEDIUM","LOW")) -> LOW
A11: ='Asset Analysis'!A11 -> GLD | B11: ='Asset Analysis'!Q11 -> 0.08 | C11: ='Asset Analysis'!R11 -> 0.075 | D11: =C11-B11 -> -0.005 | E11: ='Data Input'!$B$8 -> 100000 | F11: =IF(ABS(D11)>E11,"YES","NO") -> NO | G11: ='Asset Analysis'!O11 -> SELL | H11: =IF(F11="YES",IF(D11<0,"BUY","SELL"),IF(AND(G11="BUY",D11<0),"ADD",IF(AND(G11="SELL",D11>0),"TRIM","HOLD"))) -> HOLD | I11: =ROUND(J11/100,0) -> 0 | J11: =ABS(D11)*'Data Input'!$B$7 -> 0.0008 | K11: =IF(H11="SELL","Check TLH","N/A") -> N/A | L11: =IF(ABS(D11)>0.03,"HIGH",IF(ABS(D11)>0.015,"MEDIUM","LOW")) -> LOW
A12: ='Asset Analysis'!A12 -> VNQ | B12: ='Asset Analysis'!Q12 -> 0.05 | C12: ='Asset Analysis'!R12 -> 0.05 | D12: =C12-B12 -> 0 | E12: ='Data Input'!$B$8 -> 100000 | F12: =IF(ABS(D12)>E12,"YES","NO") -> NO | G12: ='Asset Analysis'!O12 -> SELL | H12: =IF(F12="YES",IF(D12<0,"BUY","SELL"),IF(AND(G12="BUY",D12<0),"ADD",IF(AND(G12="SELL",D12>0),"TRIM","HOLD"))) -> HOLD | I12: =ROUND(J12/100,0) -> 0 | J12: =ABS(D12)*'Data Input'!$B$7 -> 0 | K12: =IF(H12="SELL","Check TLH","N/A") -> N/A | L12: =IF(ABS(D12)>0.03,"HIGH",IF(ABS(D12)>0.015,"MEDIUM","LOW")) -> LOW
A13: ='Asset Analysis'!A13 -> XLK | B13: ='Asset Analysis'!Q13 -> 0.08 | C13: ='Asset Analysis'!R13 -> 0.09 | D13: =C13-B13 -> 0.01 | E13: ='Data Input'!$B$8 -> 100000 | F13: =IF(ABS(D13)>E13,"YES","NO") -> NO | G13: ='Asset Analysis'!O13 -> SELL | H13: =IF(F13="YES",IF(D13<0,"BUY","SELL"),IF(AND(G13="BUY",D13<0),"ADD",IF(AND(G13="SELL",D13>0),"TRIM","HOLD"))) -> TRIM | I13: =ROUND(J13/100,0) -> 0 | J13: =ABS(D13)*'Data Input'!$B$7 -> 0.0016 | K13: =IF(H13="SELL","Check TLH","N/A") -> N/A | L13: =IF(ABS(D13)>0.03,"HIGH",IF(ABS(D13)>0.015,"MEDIUM","LOW")) -> LOW
A14: ='Asset Analysis'!A14 -> XLV | B14: ='Asset Analysis'!Q14 -> 0.04 | C14: ='Asset Analysis'!R14 -> 0.035 | D14: =C14-B14 -> -0.005 | E14: ='Data Input'!$B$8 -> 100000 | F14: =IF(ABS(D14)>E14,"YES","NO") -> NO | G14: ='Asset Analysis'!O14 -> SELL | H14: =IF(F14="YES",IF(D14<0,"BUY","SELL"),IF(AND(G14="BUY",D14<0),"ADD",IF(AND(G14="SELL",D14>0),"TRIM","HOLD"))) -> HOLD | I14: =ROUND(J14/100,0) -> 0 | J14: =ABS(D14)*'Data Input'!$B$7 -> 0.0008 | K14: =IF(H14="SELL","Check TLH","N/A") -> N/A | L14: =IF(ABS(D14)>0.03,"HIGH",IF(ABS(D14)>0.015,"MEDIUM","LOW")) -> LOW
A15: ='Asset Analysis'!A15 -> XLE | B15: ='Asset Analysis'!Q15 -> 0.03 | C15: ='Asset Analysis'!R15 -> 0.03 | D15: =C15-B15 -> 0 | E15: ='Data Input'!$B$8 -> 100000 | F15: =IF(ABS(D15)>E15,"YES","NO") -> NO | G15: ='Asset Analysis'!O15 -> SELL | H15: =IF(F15="YES",IF(D15<0,"BUY","SELL"),IF(AND(G15="BUY",D15<0),"ADD",IF(AND(G15="SELL",D15>0),"TRIM","HOLD"))) -> HOLD | I15: =ROUND(J15/100,0) -> 0 | J15: =ABS(D15)*'Data Input'!$B$7 -> 0 | K15: =IF(H15="SELL","Check TLH","N/A") -> N/A | L15: =IF(ABS(D15)>0.03,"HIGH",IF(ABS(D15)>0.015,"MEDIUM","LOW")) -> LOW
... A27: ='Asset Analysis'!A27 -> PIMIX | B27: ='Asset Analysis'!Q27 -> 0 | C27: ='Asset Analysis'!R27 -> 0 | D27: =C27-B27 -> 0 | E27: ='Data Input'!$B$8 -> 100000 | F27: =IF(ABS(D27)>E27,"YES","NO") -> NO | G27: ='Asset Analysis'!O27 -> SELL | H27: =IF(F27="YES",IF(D27<0,"BUY","SELL"),IF(AND(G27="BUY",D27<0),"ADD",IF(AND(G27="SELL",D27>0),"TRIM","HOLD"))) -> HOLD | I27: =ROUND(J27/100,0) -> 0 | J27: =ABS(D27)*'Data Input'!$B$7 -> 0 | K27: =IF(H27="SELL","Check TLH","N/A") -> N/A | L27: =IF(ABS(D27)>0.03,"HIGH",IF(ABS(D27)>0.015,"MEDIUM","LOW")) -> LOW
A29: Total Trades | J29: =SUM(J4:J27) -> 0.0192
A30: # Rebalance Actions | J30: =COUNTIF(H4:H27,"<>"&"HOLD") -> 8

Sheet Portfolio Construction
A1: STRATEGIC ALLOCATION — Bands & status computed
A3: Asset Class | B3: Min% | C3: Target% | D3: Max% | E3: Current% | F3: Deviation | G3: Status
A4: US Large Cap | B4: 0.15 | C4: 0.3 | D4: 0.45 | E4: 0.3 | F4: =E4-C4 -> 0 | G4: =IF(AND(E4>=B4,E4<=D4),"OK","⚠ OUT OF BAND") -> OK
A5: US Small/Mid | B5: 0 | C5: 0.05 | D5: 0.15 | E5: 0.06 | F5: =E5-C5 -> 0.01 | G5: =IF(AND(E5>=B5,E5<=D5),"OK","⚠ OUT OF BAND") -> OK
A6: Intl Developed | B6: 0.05 | C6: 0.1 | D6: 0.2 | E6: 0.09 | F6: =E6-C6 -> -0.01 | G6: =IF(AND(E6>=B6,E6<=D6),"OK","⚠ OUT OF BAND") -> OK
A7: Emerging Markets | B7: 0 | C7: 0.05 | D7: 0.1 | E7: 0.05 | F7: =E7-C7 -> 0 | G7: =IF(AND(E7>=B7,E7<=D7),"OK","⚠ OUT OF BAND") -> OK
A8: IG Bonds | B8: 0.1 | C8: 0.15 | D8: 0.3 | E8: 0.16 | F8: =E8-C8 -> 0.01 | G8: =IF(AND(E8>=B8,E8<=D8),"OK","⚠ OUT OF BAND") -> OK
A9: Long Treasury | B9: 0 | C9: 0.05 | D9: 0.15 | E9: 0.04 | F9: =E9-C9 -> -0.01 | G9: =IF(AND(E9>=B9,E9<=D9),"OK","⚠ OUT OF BAND") -> OK
A10: REITs | B10: 0 | C10: 0.05 | D10: 0.1 | E10: 0.05 | F10: =E10-C10 -> 0 | G10: =IF(AND(E10>=B10,E10<=D10),"OK","⚠ OUT OF BAND") -> OK
A11: Gold/Commodities | B11: 0 | C11: 0.1 | D11: 0.15 | E11: 0.11 | F11: =E11-C11 -> 0.01 | G11: =IF(AND(E11>=B11,E11<=D11),"OK","⚠ OUT OF BAND") -> OK
A12: Managed Futures | B12: 0 | C12: 0.08 | D12: 0.15 | E12: 0.07 | F12: =E12-C12 -> -0.01 | G12: =IF(AND(E12>=B12,E12<=D12),"OK","⚠ OUT OF BAND") -> OK
A13: Tail Hedges | B13: 0 | C13: 0.03 | D13: 0.07 | E13: 0.03 | F13: =E13-C13 -> 0 | G13: =IF(AND(E13>=B13,E13<=D13),"OK","⚠ OUT OF BAND") -> OK
A14: Cash | B14: 0 | C14: 0.04 | D14: 0.2 | E14: 0.05 | F14: =E14-C14 -> 0.01 | G14: =IF(AND(E14>=B14,E14<=D14),"OK","⚠ OUT OF BAND") -> OK
A15: TOTAL | C15: =SUM(C4:C14) -> 1 | E15: =SUM(E4:E14) -> 1.01

Sheet Trading Desk
A1: TRADING DESK & EXECUTION
A3: INVIOLABLE TRADING PROTOCOLS
A4: 1. Limit Orders Only — No market orders except emergency risk reduction
A5: 2. 5% Daily Limit — No single trade > 5% of portfolio value
A6: 3. DWA Confirmation — No BUY on assets with DWA < 50
A7: 4. Tax-Loss Harvest — Check TLH before any SELL
A8: 5. Cash Trigger Override — If triggered, prioritize risk reduction
A9: 6. OPEX Awareness — No large trades within 2 days of OPEX
A10: 7. Sells Before Buys — All sells executed before buy orders
A11: 8. Post-Trade Verify — Confirm allocations match targets
A12: 9. Buffered ETF Check — Review regime score before equity adds
A15: EXECUTION CHECKLIST
... A27: ☐ Schedule next rebalance

Sheet Screening Universe
A1: SCREENING UNIVERSE — Ticker inventory with auto-scoring & add/delete recommendations
A2: Blue = manual input or YCharts paste | Black = formula | Red = YCharts Add-In formula (auto-populates) | Green = cross-sheet reference
A4: SCREENING THRESHOLDS (adjust these to change recommendations)
A5: Min Sharpe to ADD | B5: 0.5 | C5: B5
A6: Min DWA Score to ADD | B6: 55 | C6: B6
A7: Min Composite to ADD | B7: 55 | C7: B7
A8: Max Vol to ADD | B8: 0.3 | C8: B8
A9: Min Return to ADD | B9: 0.05 | C9: B9
A10: Max Sharpe to DELETE | B10: 0.2 | C10: B10
A11: Max DWA Score to DELETE | B11: 35 | C11: B11
A12: Max Composite to DELETE | B12: 35 | C12: B12
A13: Max Drawdown to DELETE | B13: 0.35 | C13: B13
A16: Ticker | B16: Name | C16: Class | D16: Sub-Class | E16: Price | F16: 1Y Return | G16: 3Y Return | H16: 5Y Return | I16: Volatility | J16: Sharpe | K16: Max DD | L16: Beta | M16: Div Yield | N16: Fwd P/E | O16: 1M Mom | P16: 3M Mom | Q16: 6M Mom | R16: 12M Mom | S16: DWA Score | T16: Trend | U16: Technical | V16: Fundamental | W16: Composite | X16: Signal | Y16: Conviction | Z16: In Portfolio? | AA16: Recommendation | AB16: Priority
A17: SPY | B17: SPDR S&P 500 | C17: US Equity | D17: Large Cap | E17: =IFERROR(ycps("SPY","price"),"") | F17: =IFERROR(ycps("SPY","one_year_return"),"") | G17: =IFERROR(ycps("SPY","three_year_annualized_return"),"") | H17: =IFERROR(ycps("SPY","five_year_annualized_return"),"") | I17: =IFERROR(ycps("SPY","one_year_volatility"),"") | J17: =IFERROR(IF(I17=0,0,(F17-'Data Input'!$B$4)/I17),0) -> 0 | K17: =IFERROR(ycps("SPY","max_drawdown_3_year"),"") | L17: =IFERROR(ycps("SPY","beta_5_year"),"") | M17: =IFERROR(ycps("SPY","dividend_yield"),"") | N17: =IFERROR(ycps("SPY","forward_pe_ratio"),"") | O17: =IFERROR(ycps("SPY","one_month_return"),"") | P17: =IFERROR(ycps("SPY","three_month_return"),"") | Q17: =IFERROR(ycps("SPY","six_month_return"),"") | R17: =IFERROR(ycps("SPY","one_year_return"),"") | S17: =IFERROR(MIN(100,MAX(0,ROUND(50+(O17*0.4+P17*0.3+Q17*0.2+R17*0.1)*200,0))),0) -> 0 | T17: =IFERROR(MIN(100,MAX(0,ROUND(50+R17*150+IF(F17>0,15,0)+IF(L17>0,5,-5),0))),0) -> 0 | U17: =IFERROR(MIN(100,MAX(0,ROUND(50+O17*200+IF(AND(O17>0,P17>0),10,-5)+IF(I17<0.2,10,-5),0))),0) -> 0 | V17: =IFERROR(MIN(100,MAX(0,ROUND(30+IF(I17>0,F17/I17,0)*40+IF(ABS(L17)<0.5,15,0)+IF(F17>0.08,10,0),0))),0) -> 0 | W17: =IFERROR(ROUND(T17*'Data Input'!$B$29+U17*'Data Input'!$B$30+V17*'Data Input'!$B$31+S17*'Data Input'!$B$32,0),0) -> 0 | X17: =IFERROR(IF(AND(W17>=70,IF(T17>=60,1,0)+IF(U17>=60,1,0)+IF(V17>=60,1,0)+IF(S17>=60,1,0)>=3),"STRONG BUY",IF(AND(W17>=60,IF(T17>=60,1,0)+IF(U17>=60,1,0)+IF(V17>=60,1,0)+IF(S17>=60,1,0)>=2),"BUY",IF(W17<35,"STRONG SELL",IF(AND(W17<45,IF(T17>=60,1,0)+IF(U17>=60,1,0)+IF(V17>=60,1,0)+IF(S17>=60,1,0)<=1),"SELL","HOLD")))),"") -> STRONG SELL | Y17: =IFERROR(IF(OR(X17="STRONG BUY",X17="STRONG SELL"),"HIGH",IF(OR(X17="BUY",X17="SELL"),"MEDIUM","NEUTRAL")),"") -> HIGH | Z17: =IFERROR(IF(COUNTIF('Asset Analysis'!$A$4:$A$27,A17)>0,"YES","NO"),"") -> YES | AA17: =IFERROR(IF(AND(Z17="NO",W17>=$B$7,J17>=$B$5,S17>=$B$6,I17<=$B$8,F17>=$B$9),"→ ADD TO PORTFOLIO",IF(AND(Z17="YES",OR(J17<=$B$10,S17<=$B$11,W17<=$B$12,K17<=-$B$13)),"→ DELETE FROM PORTFOLIO",IF(AND(Z17="YES",X17="HOLD"),"HOLD — MONITOR",IF(AND(Z17="YES",OR(X17="BUY",X17="STRONG BUY")),"HOLD — STRONG",IF(Z17="NO","NOT QUALIFIED","REVIEW"))))),"") -> → DELETE FROM PORTFOLIO | AB17: =IFERROR(IF(AA17="→ ADD TO PORTFOLIO",IF(W17>=70,"P1 — IMMEDIATE",IF(W17>=60,"P2 — THIS WEEK","P3 — NEXT REBALANCE")),IF(AA17="→ DELETE FROM PORTFOLIO","P1 — IMMEDIATE","—")),"") -> P1 — IMMEDIATE
A18: VOO | B18: Vanguard S&P 500 | C18: US Equity | D18: Large Cap | E18: =IFERROR(ycps("VOO","price"),"") | F18: =IFERROR(ycps("VOO","one_year_return"),"") | G18: =IFERROR(ycps("VOO","three_year_annualized_return"),"") | H18: =IFERROR(ycps("VOO","five_year_annualized_return"),"") | I18: =IFERROR(ycps("VOO","one_year_volatility"),"") | J18: =IFERROR(IF(I18=0,0,(F18-'Data Input'!$B$4)/I18),0) -> 0 | K18: =IFERROR(ycps("VOO","max_drawdown_3_year"),"") | L18: =IFERROR(ycps("VOO","beta_5_year"),"") | M18: =IFERROR(ycps("VOO","dividend_yield"),"") | N18: =IFERROR(ycps("VOO","forward_pe_ratio"),"") | O18: =IFERROR(ycps("VOO","one_month_return"),"") | P18: =IFERROR(ycps("VOO","three_month_return"),"") | Q18: =IFERROR(ycps("VOO","six_month_return"),"") | R18: =IFERROR(ycps("VOO","one_year_return"),"") | S18: =IFERROR(MIN(100,MAX(0,ROUND(50+(O18*0.4+P18*0.3+Q18*0.2+R18*0.1)*200,0))),0) -> 0 | T18: =IFERROR(MIN(100,MAX(0,ROUND(50+R18*150+IF(F18>0,15,0)+IF(L18>0,5,-5),0))),0) -> 0 | U18: =IFERROR(MIN(100,MAX(0,ROUND(50+O18*200+IF(AND(O18>0,P18>0),10,-5)+IF(I18<0.2,10,-5),0))),0) -> 0 | V18: =IFERROR(MIN(100,MAX(0,ROUND(30+IF(I18>0,F18/I18,0)*40+IF(ABS(L18)<0.5,15,0)+IF(F18>0.08,10,0),0))),0) -> 0 | W18: =IFERROR(ROUND(T18*'Data Input'!$B$29+U18*'Data Input'!$B$30+V18*'Data Input'!$B$31+S18*'Data Input'!$B$32,0),0) -> 0 | X18: =IFERROR(IF(AND(W18>=70,IF(T18>=60,1,0)+IF(U18>=60,1,0)+IF(V18>=60,1,0)+IF(S18>=60,1,0)>=3),"STRONG BUY",IF(AND(W18>=60,IF(T18>=60,1,0)+IF(U18>=60,1,0)+IF(V18>=60,1,0)+IF(S18>=60,1,0)>=2),"BUY",IF(W18<35,"STRONG SELL",IF(AND(W18<45,IF(T18>=60,1,0)+IF(U18>=60,1,0)+IF(V18>=60,1,0)+IF(S18>=60,1,0)<=1),"SELL","HOLD")))),"") -> STRONG SELL | Y18: =IFERROR(IF(OR(X18="STRONG BUY",X18="STRONG SELL"),"HIGH",IF(OR(X18="BUY",X18="SELL"),"MEDIUM","NEUTRAL")),"") -> HIGH | Z18: =IFERROR(IF(COUNTIF('Asset Analysis'!$A$4:$A$27,A18)>0,"YES","NO"),"") -> NO | AA18: =IFERROR(IF(AND(Z18="NO",W18>=$B$7,J18>=$B$5,S18>=$B$6,I18<=$B$8,F18>=$B$9),"→ ADD TO PORTFOLIO",IF(AND(Z18="YES",OR(J18<=$B$10,S18<=$B$11,W18<=$B$12,K18<=-$B$13)),"→ DELETE FROM PORTFOLIO",IF(AND(Z18="YES",X18="HOLD"),"HOLD — MONITOR",IF(AND(Z18="YES",OR(X18="BUY",X18="STRONG BUY")),"HOLD — STRONG",IF(Z18="NO","NOT QUALIFIED","REVIEW"))))),"") -> NOT QUALIFIED | AB18: =IFERROR(IF(AA18="→ ADD TO PORTFOLIO",IF(W18>=70,"P1 — IMMEDIATE",IF(W18>=60,"P2 — THIS WEEK","P3 — NEXT REBALANCE")),IF(AA18="→ DELETE FROM PORTFOLIO","P1 — IMMEDIATE","—")),"") -> —
A19: QQQ | B19: Invesco Nasdaq 100 | C19: US Equity | D19: Large Growth | E19: =IFERROR(ycps("QQQ","price"),"") | F19: =IFERROR(ycps("QQQ","one_year_return"),"") | G19: =IFERROR(ycps("QQQ","three_year_annualized_return"),"") | H19: =IFERROR(ycps("QQQ","five_year_annualized_return"),"") | I19: =IFERROR(ycps("QQQ","one_year_volatility"),"") | J19: =IFERROR(IF(I19=0,0,(F19-'Data Input'!$B$4)/I19),0) -> 0 | K19: =IFERROR(ycps("QQQ","max_drawdown_3_year"),"") | L19: =IFERROR(ycps("QQQ","beta_5_year"),"") | M19: =IFERROR(ycps("QQQ","dividend_yield"),"") | N19: =IFERROR(ycps("QQQ","forward_pe_ratio"),"") | O19: =IFERROR(ycps("QQQ","one_month_return"),"") | P19: =IFERROR(ycps("QQQ","three_month_return"),"") | Q19: =IFERROR(ycps("QQQ","six_month_return"),"") | R19: =IFERROR(ycps("QQQ","one_year_return"),"") | S19: =IFERROR(MIN(100,MAX(0,ROUND(50+(O19*0.4+P19*0.3+Q19*0.2+R19*0.1)*200,0))),0) -> 0 | T19: =IFERROR(MIN(100,MAX(0,ROUND(50+R19*150+IF(F19>0,15,0)+IF(L19>0,5,-5),0))),0) -> 0 | U19: =IFERROR(MIN(100,MAX(0,ROUND(50+O19*200+IF(AND(O19>0,P19>0),10,-5)+IF(I19<0.2,10,-5),0))),0) -> 0 | V19: =IFERROR(MIN(100,MAX(0,ROUND(30+IF(I19>0,F19/I19,0)*40+IF(ABS(L19)<0.5,15,0)+IF(F19>0.08,10,0),0))),0) -> 0 | W19: =IFERROR(ROUND(T19*'Data Input'!$B$29+U19*'Data Input'!$B$30+V19*'Data Input'!$B$31+S19*'Data Input'!$B$32,0),0) -> 0 | X19: =IFERROR(IF(AND(W19>=70,IF(T19>=60,1,0)+IF(U19>=60,1,0)+IF(V19>=60,1,0)+IF(S19>=60,1,0)>=3),"STRONG BUY",IF(AND(W19>=60,IF(T19>=60,1,0)+IF(U19>=60,1,0)+IF(V19>=60,1,0)+IF(S19>=60,1,0)>=2),"BUY",IF(W19<35,"STRONG SELL",IF(AND(W19<45,IF(T19>=60,1,0)+IF(U19>=60,1,0)+IF(V19>=60,1,0)+IF(S19>=60,1,0)<=1),"SELL","HOLD")))),"") -> STRONG SELL | Y19: =IFERROR(IF(OR(X19="STRONG BUY",X19="STRONG SELL"),"HIGH",IF(OR(X19="BUY",X19="SELL"),"MEDIUM","NEUTRAL")),"") -> HIGH | Z19: =IFERROR(IF(COUNTIF('Asset Analysis'!$A$4:$A$27,A19)>0,"YES","NO"),"") -> YES | AA19: =IFERROR(IF(AND(Z19="NO",W19>=$B$7,J19>=$B$5,S19>=$B$6,I19<=$B$8,F19>=$B$9),"→ ADD TO PORTFOLIO",IF(AND(Z19="YES",OR(J19<=$B$10,S19<=$B$11,W19<=$B$12,K19<=-$B$13)),"→ DELETE FROM PORTFOLIO",IF(AND(Z19="YES",X19="HOLD"),"HOLD — MONITOR",IF(AND(Z19="YES",OR(X19="BUY",X19="STRONG BUY")),"HOLD — STRONG",IF(Z19="NO","NOT QUALIFIED","REVIEW"))))),"") -> → DELETE FROM PORTFOLIO | AB19: =IFERROR(IF(AA19="→ ADD TO PORTFOLIO",IF(W19>=70,"P1 — IMMEDIATE",IF(W19>=60,"P2 — THIS WEEK","P3 — NEXT REBALANCE")),IF(AA19="→ DELETE FROM PORTFOLIO","P1 — IMMEDIATE","—")),"") -> P1 — IMMEDIATE
A20: VTI | B20: Vanguard Total Stock | C20: US Equity | D20: Broad | E20: =IFERROR(ycps("VTI","price"),"") | F20: =IFERROR(ycps("VTI","one_year_return"),"") | G20: =IFERROR(ycps("VTI","three_year_annualized_return"),"") | H20: =IFERROR(ycps("VTI","five_year_annualized_return"),"") | I20: =IFERROR(ycps("VTI","one_year_volatility"),"") | J20: =IFERROR(IF(I20=0,0,(F20-'Data Input'!$B$4)/I20),0) -> 0 | K20: =IFERROR(ycps("VTI","max_drawdown_3_year"),"") | L20: =IFERROR(ycps("VTI","beta_5_year"),"") | M20: =IFERROR(ycps("VTI","dividend_yield"),"") | N20: =IFERROR(ycps("VTI","forward_pe_ratio"),"") | O20: =IFERROR(ycps("VTI","one_month_return"),"") | P20: =IFERROR(ycps("VTI","three_month_return"),"") | Q20: =IFERROR(ycps("VTI","six_month_return"),"") | R20: =IFERROR(ycps("VTI","one_year_return"),"") | S20: =IFERROR(MIN(100,MAX(0,ROUND(50+(O20*0.4+P20*0.3+Q20*0.2+R20*0.1)*200,0))),0) -> 0 | T20: =IFERROR(MIN(100,MAX(0,ROUND(50+R20*150+IF(F20>0,15,0)+IF(L20>0,5,-5),0))),0) -> 0 | U20: =IFERROR(MIN(100,MAX(0,ROUND(50+O20*200+IF(AND(O20>0,P20>0),10,-5)+IF(I20<0.2,10,-5),0))),0) -> 0 | V20: =IFERROR(MIN(100,MAX(0,ROUND(30+IF(I20>0,F20/I20,0)*40+IF(ABS(L20)<0.5,15,0)+IF(F20>0.08,10,0),0))),0) -> 0 | W20: =IFERROR(ROUND(T20*'Data Input'!$B$29+U20*'Data Input'!$B$30+V20*'Data Input'!$B$31+S20*'Data Input'!$B$32,0),0) -> 0 | X20: =IFERROR(IF(AND(W20>=70,IF(T20>=60,1,0)+IF(U20>=60,1,0)+IF(V20>=60,1,0)+IF(S20>=60,1,0)>=3),"STRONG BUY",IF(AND(W20>=60,IF(T20>=60,1,0)+IF(U20>=60,1,0)+IF(V20>=60,1,0)+IF(S20>=60,1,0)>=2),"BUY",IF(W20<35,"STRONG SELL",IF(AND(W20<45,IF(T20>=60,1,0)+IF(U20>=60,1,0)+IF(V20>=60,1,0)+IF(S20>=60,1,0)<=1),"SELL","HOLD")))),"") -> STRONG SELL | Y20: =IFERROR(IF(OR(X20="STRONG BUY",X20="STRONG SELL"),"HIGH",IF(OR(X20="BUY",X20="SELL"),"MEDIUM","NEUTRAL")),"") -> HIGH | Z20: =IFERROR(IF(COUNTIF('Asset Analysis'!$A$4:$A$27,A20)>0,"YES","NO"),"") -> NO | AA20: =IFERROR(IF(AND(Z20="NO",W20>=$B$7,J20>=$B$5,S20>=$B$6,I20<=$B$8,F20>=$B$9),"→ ADD TO PORTFOLIO",IF(AND(Z20="YES",OR(J20<=$B$10,S20<=$B$11,W20<=$B$12,K20<=-$B$13)),"→ DELETE FROM PORTFOLIO",IF(AND(Z20="YES",X20="HOLD"),"HOLD — MONITOR",IF(AND(Z20="YES",OR(X20="BUY",X20="STRONG BUY")),"HOLD — STRONG",IF(Z20="NO","NOT QUALIFIED","REVIEW"))))),"") -> NOT QUALIFIED | AB20: =IFERROR(IF(AA20="→ ADD TO PORTFOLIO",IF(W20>=70,"P1 — IMMEDIATE",IF(W20>=60,"P2 — THIS WEEK","P3 — NEXT REBALANCE")),IF(AA20="→ DELETE FROM PORTFOLIO","P1 — IMMEDIATE","—")),"") -> —
A21: IVV | B21: iShares Core S&P 500 | C21: US Equity | D21: Large Cap | E21: =IFERROR(ycps("IVV","price"),"") | F21: =IFERROR(ycps("IVV","one_year_return"),"") | G21: =IFERROR(ycps("IVV","three_year_annualized_return"),"") | H21: =IFERROR(ycps("IVV","five_year_annualized_return"),"") | I21: =IFERROR(ycps("IVV","one_year_volatility"),"") | J21: =IFERROR(IF(I21=0,0,(F21-'Data Input'!$B$4)/I21),0) -> 0 | K21: =IFERROR(ycps("IVV","max_drawdown_3_year"),"") | L21: =IFERROR(ycps("IVV","beta_5_year"),"") | M21: =IFERROR(ycps("IVV","dividend_yield"),"") | N21: =IFERROR(ycps("IVV","forward_pe_ratio"),"") | O21: =IFERROR(ycps("IVV","one_month_return"),"") | P21: =IFERROR(ycps("IVV","three_month_return"),"") | Q21: =IFERROR(ycps("IVV","six_month_return"),"") | R21: =IFERROR(ycps("IVV","one_year_return"),"") | S21: =IFERROR(MIN(100,MAX(0,ROUND(50+(O21*0.4+P21*0.3+Q21*0.2+R21*0.1)*200,0))),0) -> 0 | T21: =IFERROR(MIN(100,MAX(0,ROUND(50+R21*150+IF(F21>0,15,0)+IF(L21>0,5,-5),0))),0) -> 0 | U21: =IFERROR(MIN(100,MAX(0,ROUND(50+O21*200+IF(AND(O21>0,P21>0),10,-5)+IF(I21<0.2,10,-5),0))),0) -> 0 | V21: =IFERROR(MIN(100,MAX(0,ROUND(30+IF(I21>0,F21/I21,0)*40+IF(ABS(L21)<0.5,15,0)+IF(F21>0.08,10,0),0))),0) -> 0 | W21: =IFERROR(ROUND(T21*'Data Input'!$B$29+U21*'Data Input'!$B$30+V21*'Data Input'!$B$31+S21*'Data Input'!$B$32,0),0) -> 0 | X21: =IFERROR(IF(AND(W21>=70,IF(T21>=60,1,0)+IF(U21>=60,1,0)+IF(V21>=60,1,0)+IF(S21>=60,1,0)>=3),"STRONG BUY",IF(AND(W21>=60,IF(T21>=60,1,0)+IF(U21>=60,1,0)+IF(V21>=60,1,0)+IF(S21>=60,1,0)>=2),"BUY",IF(W21<35,"STRONG SELL",IF(AND(W21<45,IF(T21>=60,1,0)+IF(U21>=60,1,0)+IF(V21>=60,1,0)+IF(S21>=60,1,0)<=1),"SELL","HOLD")))),"") -> STRONG SELL | Y21: =IFERROR(IF(OR(X21="STRONG BUY",X21="STRONG SELL"),"HIGH",IF(OR(X21="BUY",X21="SELL"),"MEDIUM","NEUTRAL")),"") -> HIGH | Z21: =IFERROR(IF(COUNTIF('Asset Analysis'!$A$4:$A$27,A21)>0,"YES","NO"),"") -> NO | AA21: =IFERROR(IF(AND(Z21="NO",W21>=$B$7,J21>=$B$5,S21>=$B$6,I21<=$B$8,F21>=$B$9),"→ ADD TO PORTFOLIO",IF(AND(Z21="YES",OR(J21<=$B$10,S21<=$B$11,W21<=$B$12,K21<=-$B$13)),"→ DELETE FROM PORTFOLIO",IF(AND(Z21="YES",X21="HOLD"),"HOLD — MONITOR",IF(AND(Z21="YES",OR(X21="BUY",X21="STRONG BUY")),"HOLD — STRONG",IF(Z21="NO","NOT QUALIFIED","REVIEW"))))),"") -> NOT QUALIFIED | AB21: =IFERROR(IF(AA21="→ ADD TO PORTFOLIO",IF(W21>=70,"P1 — IMMEDIATE",IF(W21>=60,"P2 — THIS WEEK","P3 — NEXT REBALANCE")),IF(AA21="→ DELETE FROM PORTFOLIO","P1 — IMMEDIATE","—")),"") -> —
A22: RSP | B22: Invesco Equal Weight S&P | C22: US Equity | D22: Equal Wt | E22: =IFERROR(ycps("RSP","price"),"") | F22: =IFERROR(ycps("RSP","one_year_return"),"") | G22: =IFERROR(ycps("RSP","three_year_annualized_return"),"") | H22: =IFERROR(ycps("RSP","five_year_annualized_return"),"") | I22: =IFERROR(ycps("RSP","one_year_volatility"),"") | J22: =IFERROR(IF(I22=0,0,(F22-'Data Input'!$B$4)/I22),0) -> 0 | K22: =IFERROR(ycps("RSP","max_drawdown_3_year"),"") | L22: =IFERROR(ycps("RSP","beta_5_year"),"") | M22: =IFERROR(ycps("RSP","dividend_yield"),"") | N22: =IFERROR(ycps("RSP","forward_pe_ratio"),"") | O22: =IFERROR(ycps("RSP","one_month_return"),"") | P22: =IFERROR(ycps("RSP","three_month_return"),"") | Q22: =IFERROR(ycps("RSP","six_month_return"),"") | R22: =IFERROR(ycps("RSP","one_year_return"),"") | S22: =IFERROR(MIN(100,MAX(0,ROUND(50+(O22*0.4+P22*0.3+Q22*0.2+R22*0.1)*200,0))),0) -> 0 | T22: =IFERROR(MIN(100,MAX(0,ROUND(50+R22*150+IF(F22>0,15,0)+IF(L22>0,5,-5),0))),0) -> 0 | U22: =IFERROR(MIN(100,MAX(0,ROUND(50+O22*200+IF(AND(O22>0,P22>0),10,-5)+IF(I22<0.2,10,-5),0))),0) -> 0 | V22: =IFERROR(MIN(100,MAX(0,ROUND(30+IF(I22>0,F22/I22,0)*40+IF(ABS(L22)<0.5,15,0)+IF(F22>0.08,10,0),0))),0) -> 0 | W22: =IFERROR(ROUND(T22*'Data Input'!$B$29+U22*'Data Input'!$B$30+V22*'Data Input'!$B$31+S22*'Data Input'!$B$32,0),0) -> 0 | X22: =IFERROR(IF(AND(W22>=70,IF(T22>=60,1,0)+IF(U22>=60,1,0)+IF(V22>=60,1,0)+IF(S22>=60,1,0)>=3),"STRONG BUY",IF(AND(W22>=60,IF(T22>=60,1,0)+IF(U22>=60,1,0)+IF(V22>=60,1,0)+IF(S22>=60,1,0)>=2),"BUY",IF(W22<35,"STRONG SELL",IF(AND(W22<45,IF(T22>=60,1,0)+IF(U22>=60,1,0)+IF(V22>=60,1,0)+IF(S22>=60,1,0)<=1),"SELL","HOLD")))),"") -> STRONG SELL | Y22: =IFERROR(IF(OR(X22="STRONG BUY",X22="STRONG SELL"),"HIGH",IF(OR(X22="BUY",X22="SELL"),"MEDIUM","NEUTRAL")),"") -> HIGH | Z22: =IFERROR(IF(COUNTIF('Asset Analysis'!$A$4:$A$27,A22)>0,"YES","NO"),"") -> NO | AA22: =IFERROR(IF(AND(Z22="NO",W22>=$B$7,J22>=$B$5,S22>=$B$6,I22<=$B$8,F22>=$B$9),"→ ADD TO PORTFOLIO",IF(AND(Z22="YES",OR(J22<=$B$10,S22<=$B$11,W22<=$B$12,K22<=-$B$13)),"→ DELETE FROM PORTFOLIO",IF(AND(Z22="YES",X22="HOLD"),"HOLD — MONITOR",IF(AND(Z22="YES",OR(X22="BUY",X22="STRONG BUY")),"HOLD — STRONG",IF(Z22="NO","NOT QUALIFIED","REVIEW"))))),"") -> NOT QUALIFIED | AB22: =IFERROR(IF(AA22="→ ADD TO PORTFOLIO",IF(W22>=70,"P1 — IMMEDIATE",IF(W22>=60,"P2 — THIS WEEK","P3 — NEXT REBALANCE")),IF(AA22="→ DELETE FROM PORTFOLIO","P1 — IMMEDIATE","—")),"") -> —
